Workbook

Sheet Leia-me
A1: SupriMax — Dicionário de Dados do Sistema 2 (Cotação Web)
A3: Finalidade | B3: Versão em planilha do dicionário de dados das vinte e duas tabelas do Sistema 2, para consulta rápida, filtro e busca. Complementa a seção 13.7 da “Documentação SupriMax”.
A4: Fonte | B4: Seção 13.7 da “Documentação SupriMax” (dicionário de dados e chaves estrangeiras). Em caso de divergência, prevalece o documento; ao alterar o schema, atualizar documento e planilha juntos.
A5: Banco de dados | B5: Banco único e compartilhado pelos Sistemas 1, 2 e 3 (Supabase/PostgreSQL). Nomes de tabelas e colunas em snake_case, sem acentos.
A7: ABAS
A8: Entidades | B8: Uma linha por tabela: descrição, contagem de colunas e FKs (fórmulas) e uso previsto pelos três sistemas.
A9: Colunas | B9: Dicionário completo: uma linha por coluna, com tipo, restrições em colunas separadas, indicação de nulo e tabela referenciada. Use os filtros do cabeçalho.
A10: Chaves Estrangeiras | B10: As 45 chaves estrangeiras do modelo lógico, com a tabela/coluna referenciada e a obrigatoriedade.
A12: SIGLAS DE RESTRIÇÃO
A13: PK | B13: Chave primária (não nula por definição).
A14: FK | B14: Chave estrangeira (referência na aba Chaves Estrangeiras).
A15: UK | B15: Unicidade (UNIQUE).
A16: NN | B16: Não nulo (NOT NULL).
A17: CK | B17: Restrição de verificação (CHECK); a regra completa está na descrição da coluna e na seção 13.4 da documentação.
A19: OBSERVAÇÕES
A20: Nulos | B20: Colunas sem NN e que não sejam PK aceitam nulo (coluna “Aceita nulo?”, calculada por fórmula).
A21: Uso pelos sistemas | B21: O uso previsto das tabelas pelos Sistemas 1 e 3 foi inferido da documentação de requisitos e ainda deve ser confirmado com os grupos responsáveis.
A22: Escopo | B22: Cobre apenas as tabelas do Sistema 2. Os dicionários dos Sistemas 1 e 3 dependem dos respectivos grupos.
A24: CONFERÊNCIA
A25: Tabelas | B25: =COUNTA(Entidades!$C$5:$C$26) -> 22
A26: Colunas | B26: =COUNTA(Colunas!$C$2:$C$213) -> 212
A27: Chaves estrangeiras | B27: =COUNTA('Chaves Estrangeiras'!$C$5:$C$49) -> 45
A28: Conferência | B28: =IF(AND(B25=22,B26=212,B27=45,Entidades!$E$27=B26,Entidades!$F$27=B27),"OK","DIVERGENTE") -> OK
A29: Referência | B29: Valores esperados, conforme a seção 13.7 da “Documentação SupriMax”: 22 tabelas, 212 colunas e 45 chaves estrangeiras. A conferência também compara os totais da aba Entidades com as abas Colunas e Chaves Estrangeiras.

Sheet Entidades
A1: Entidades do Sistema 2 — visão geral
A2: Contagens calculadas por fórmula a partir da aba Colunas. Uso previsto pelos Sistemas 1 e 3: inferido da documentação de requisitos, a confirmar com os grupos responsáveis.
A4: Nº | B4: Entidade | C4: Tabela | D4: Descrição | E4: Nº de colunas | F4: Nº de FKs | G4: Nº de colunas com CK | H4: Uso previsto — Sistema 1 (mobile) | I4: Uso previsto — Sistema 2 (cotação) | J4: Uso previsto — Sistema 3 (painel) | K4: Origem / observação (checklist)
A5: 1 | B5: Operador/Vendedor | C5: operador | D5: Usuário do sistema em qualquer perfil (vendedor, operador, operador chefe, fiscal, financeiro ou gestor). Login unificado com os Sistemas 1 e 3; o vendedor responde por uma carteira de clientes. | E5: =COUNTIF(Colunas!$A$2:$A$213,C5) -> 11 | F5: =COUNTIFS(Colunas!$A$2:$A$213,C5,Colunas!$F$2:$F$213,"X") -> 0 | G5: =COUNTIFS(Colunas!$A$2:$A$213,C5,Colunas!$I$2:$I$213,"X") -> 3 | H5: Login unificado | I5: Login, perfis e gestão de usuários | J5: Login unificado | K5: Usuário em qualquer perfil (vendedor, operador, operador chefe, fiscal, financeiro ou gestor): login, bloqueio após tentativas inválidas e recuperação de senha.
A6: 2 | B6: Cliente | C6: cliente | D6: Empresa cliente B2B, identificada por CNPJ. Cada cliente pertence a um único vendedor (carteira de clientes). | E6: =COUNTIF(Colunas!$A$2:$A$213,C6) -> 13 | F6: =COUNTIFS(Colunas!$A$2:$A$213,C6,Colunas!$F$2:$F$213,"X") -> 1 | G6: =COUNTIFS(Colunas!$A$2:$A$213,C6,Colunas!$I$2:$I$213,"X") -> 3 | H6: Consulta ao abrir pedido | I6: Cadastro e consulta | J6: Consulta | K6: Cliente B2B por CNPJ; vinculado a um vendedor responsável (carteira de clientes).
A7: 3 | B7: Endereço do Cliente | C7: endereco_cliente | D7: Endereço cadastral ou local de entrega de um cliente (relação 1:N). | E7: =COUNTIF(Colunas!$A$2:$A$213,C7) -> 10 | F7: =COUNTIFS(Colunas!$A$2:$A$213,C7,Colunas!$F$2:$F$213,"X") -> 1 | G7: =COUNTIFS(Colunas!$A$2:$A$213,C7,Colunas!$I$2:$I$213,"X") -> 1 | H7: Consulta ao abrir pedido | I7: Cadastro e consulta | J7: Consulta | K7: Um ou mais endereços/locais de entrega por cliente.
A8: 4 | B8: Produto | C8: produto | D8: Item do catálogo, sem marca ou embalagem definidas. Compartilhado com os Sistemas 1 e 3. | E8: =COUNTIF(Colunas!$A$2:$A$213,C8) -> 7 | F8: =COUNTIFS(Colunas!$A$2:$A$213,C8,Colunas!$F$2:$F$213,"X") -> 0 | G8: =COUNTIFS(Colunas!$A$2:$A$213,C8,Colunas!$I$2:$I$213,"X") -> 0 | H8: Consulta de preços e disponibilidade | I8: Cadastro e consulta | J8: Controle de estoque e indicadores | K8: Código interno, descrição e NCM.
A9: 5 | B9: Variação do Produto | C9: variacao_produto | D9: Combinação de marca e tamanho/embalagem de um produto; é o item de estoque físico independente. O preço não fica aqui: vem das Faixas de Preço (venda avulsa) ou dos Fardos (venda fechada). | E9: =COUNTIF(Colunas!$A$2:$A$213,C9) -> 5 | F9: =COUNTIFS(Colunas!$A$2:$A$213,C9,Colunas!$F$2:$F$213,"X") -> 1 | G9: =COUNTIFS(Colunas!$A$2:$A$213,C9,Colunas!$I$2:$I$213,"X") -> 1 | H9: Consulta de preços e disponibilidade | I9: Cadastro e consulta | J9: Controle de estoque e indicadores | K9: Marca e tamanho/embalagem; item de estoque físico independente.
A10: 6 | B10: Faixa de Preço | C10: faixa_preco | D10: Faixa de preço para venda avulsa de uma variação, por quantidade mínima (ex.: 1 a 3 un. = R$ 25,00; 4+ un. = R$ 19,00). | E10: =COUNTIF(Colunas!$A$2:$A$213,C10) -> 4 | F10: =COUNTIFS(Colunas!$A$2:$A$213,C10,Colunas!$F$2:$F$213,"X") -> 1 | G10: =COUNTIFS(Colunas!$A$2:$A$213,C10,Colunas!$I$2:$I$213,"X") -> 2 | H10: Consulta de preços e disponibilidade | I10: Cadastro e consulta | J10: Controle de estoque e indicadores | K10: Preço por faixa de quantidade, para venda avulsa da variação.
A11: 7 | B11: Fardo | C11: fardo | D11: Opção de venda em pacote fechado de uma variação. Uma variação pode ter mais de um tipo de fardo, cada um com preço próprio. | E11: =COUNTIF(Colunas!$A$2:$A$213,C11) -> 4 | F11: =COUNTIFS(Colunas!$A$2:$A$213,C11,Colunas!$F$2:$F$213,"X") -> 1 | G11: =COUNTIFS(Colunas!$A$2:$A$213,C11,Colunas!$I$2:$I$213,"X") -> 2 | H11: Consulta de preços e disponibilidade | I11: Cadastro e consulta | J11: Controle de estoque e indicadores | K11: Preço fixo por pacote fechado da variação.
A12: 8 | B12: Orçamento | C12: orcamento | D12: Orçamento (cotação de venda) emitido a um cliente por um operador/vendedor, com versões e status (seção 4.6). O orçamento emitido é imutável; os valores aceitos ficam em resposta_orcamento. | E12: =COUNTIF(Colunas!$A$2:$A$213,C12) -> 31 | F12: =COUNTIFS(Colunas!$A$2:$A$213,C12,Colunas!$F$2:$F$213,"X") -> 5 | G12: =COUNTIFS(Colunas!$A$2:$A$213,C12,Colunas!$I$2:$I$213,"X") -> 15 | H12: Lê o orçamento pronto; registra o follow-up | I12: Monta, edita, emite e versiona | J12: Lê para indicadores (RF17) | K12: Cabeçalho do orçamento: número, validade, status, condições, vínculo com o pedido e com a versão original.
A13: 9 | B13: Item de Orçamento | C13: item_orcamento | D13: Linha do orçamento: uma variação, comprada por fardo fechado ou avulso. | E13: =COUNTIF(Colunas!$A$2:$A$213,C13) -> 12 | F13: =COUNTIFS(Colunas!$A$2:$A$213,C13,Colunas!$F$2:$F$213,"X") -> 4 | G13: =COUNTIFS(Colunas!$A$2:$A$213,C13,Colunas!$I$2:$I$213,"X") -> 8 | H13: Lê o orçamento pronto; registra o follow-up | I13: Monta, edita, emite e versiona | J13: Lê para indicadores (RF17) | K13: Linha do orçamento, por fardo fechado ou por faixa avulsa.
A14: 10 | B14: Reserva de Estoque | C14: reserva_estoque | D14: Reserva de saldo físico criada, na emissão do orçamento, para cada item (relação 1:1). Expira junto com a validade do orçamento. | E14: =COUNTIF(Colunas!$A$2:$A$213,C14) -> 5 | F14: =COUNTIFS(Colunas!$A$2:$A$213,C14,Colunas!$F$2:$F$213,"X") -> 1 | G14: =COUNTIFS(Colunas!$A$2:$A$213,C14,Colunas!$I$2:$I$213,"X") -> 2 | H14: Lê o orçamento pronto; registra o follow-up | I14: Monta, edita, emite e versiona | J14: Lê para indicadores (RF17) | K14: Reserva de saldo físico criada, na emissão, para cada item de orçamento (1:1); baixada no aceite.
A15: 11 | B15: Anexo do Orçamento | C15: anexo_orcamento | D15: Arquivo anexado ao orçamento, como descritivo técnico ou material de apoio. | E15: =COUNTIF(Colunas!$A$2:$A$213,C15) -> 7 | F15: =COUNTIFS(Colunas!$A$2:$A$213,C15,Colunas!$F$2:$F$213,"X") -> 1 | G15: =COUNTIFS(Colunas!$A$2:$A$213,C15,Colunas!$I$2:$I$213,"X") -> 1 | H15: Consulta o resultado | I15: Cadastro e consulta | J15: — | K15: Descritivos técnicos e materiais de apoio do orçamento.
A16: 12 | B16: Análise de Crédito | C16: analise_credito | D16: Análise de crédito de um cliente, opcionalmente ligada a um orçamento. | E16: =COUNTIF(Colunas!$A$2:$A$213,C16) -> 7 | F16: =COUNTIFS(Colunas!$A$2:$A$213,C16,Colunas!$F$2:$F$213,"X") -> 3 | G16: =COUNTIFS(Colunas!$A$2:$A$213,C16,Colunas!$I$2:$I$213,"X") -> 2 | H16: Consulta o resultado | I16: Cadastro e consulta | J16: — | K16: Resultado da análise de crédito do cliente.
... A26: 22 | B26: Movimentação de Estoque | C26: movimentacao_estoque | D26: Histórico de toda variação do estoque físico: entradas de mercadoria, baixas no aceite, ajustes e estornos. | E26: =COUNTIF(Colunas!$A$2:$A$213,C26) -> 9 | F26: =COUNTIFS(Colunas!$A$2:$A$213,C26,Colunas!$F$2:$F$213,"X") -> 4 | G26: =COUNTIFS(Colunas!$A$2:$A$213,C26,Colunas!$I$2:$I$213,"X") -> 3 | H26: — | I26: Registra entradas, ajustes e baixas | J26: Controle de estoque | K26: Histórico de entradas, baixas no aceite, ajustes e estornos do estoque físico.
D27: Total | E27: =SUM(E5:E26) -> 212 | F27: =SUM(F5:F26) -> 45 | G27: =SUM(G5:G26) -> 74

Sheet Colunas
A1: Tabela | B1: Nº | C1: Coluna | D1: Tipo | E1: PK | F1: FK | G1: UK | H1: NN | I1: CK | J1: Aceita nulo? | K1: Referencia (FK) | L1: Descrição
A2: operador | B2: 1 | C2: id_operador | D2: INTEGER | E2: X | J2: =IF(OR(E2="X",H2="X"),"Não","Sim") -> Não | L2: Identificador do operador (auto-incremento).
A3: operador | B3: 2 | C3: usuario | D3: VARCHAR(50) | G3: X | H3: X | J3: =IF(OR(E3="X",H3="X"),"Não","Sim") -> Não | L3: Nome de usuário usado no login.
A4: operador | B4: 3 | C4: email | D4: VARCHAR(120) | G4: X | H4: X | J4: =IF(OR(E4="X",H4="X"),"Não","Sim") -> Não | L4: E-mail do usuário; recebe o link de definição e de recuperação de senha.
A5: operador | B5: 4 | C5: senha_hash | D5: VARCHAR(255) | H5: X | J5: =IF(OR(E5="X",H5="X"),"Não","Sim") -> Não | L5: Senha armazenada de forma criptografada (RNF01).
A6: operador | B6: 5 | C6: perfil | D6: VARCHAR(20) | H6: X | I6: X | J6: =IF(OR(E6="X",H6="X"),"Não","Sim") -> Não | L6: VENDEDOR, OPERADOR, OPERADOR_CHEFE, FISCAL, FINANCEIRO ou GESTOR.
A7: operador | B7: 6 | C7: status | D7: VARCHAR(7) | H7: X | I7: X | J7: =IF(OR(E7="X",H7="X"),"Não","Sim") -> Não | L7: ATIVO ou INATIVO. Padrão: ATIVO.
A8: operador | B8: 7 | C8: tentativas_login_invalidas | D8: SMALLINT | H8: X | I8: X | J8: =IF(OR(E8="X",H8="X"),"Não","Sim") -> Não | L8: Contador de tentativas de login inválidas consecutivas; 0 a 3. Padrão: 0.
A9: operador | B9: 8 | C9: bloqueado_ate | D9: TIMESTAMP | J9: =IF(OR(E9="X",H9="X"),"Não","Sim") -> Sim | L9: Momento até o qual o login fica bloqueado; nulo quando não há bloqueio ativo.
A10: operador | B10: 9 | C10: token_recuperacao_senha | D10: VARCHAR(255) | G10: X | J10: =IF(OR(E10="X",H10="X"),"Não","Sim") -> Sim | L10: Token de redefinição de senha enviado por e-mail; nulo fora do fluxo de recuperação.
A11: operador | B11: 10 | C11: validade_token | D11: TIMESTAMP | J11: =IF(OR(E11="X",H11="X"),"Não","Sim") -> Sim | L11: Data e hora limite de uso do token de recuperação; nula quando não há token ativo.
A12: operador | B12: 11 | C12: data_cadastro | D12: TIMESTAMP | H12: X | J12: =IF(OR(E12="X",H12="X"),"Não","Sim") -> Não | L12: Data e hora de criação da conta. Padrão: momento atual.
A13: cliente | B13: 1 | C13: id_cliente | D13: INTEGER | E13: X | J13: =IF(OR(E13="X",H13="X"),"Não","Sim") -> Não | L13: Identificador do cliente (auto-incremento).
A14: cliente | B14: 2 | C14: cnpj | D14: CHAR(14) | G14: X | H14: X | J14: =IF(OR(E14="X",H14="X"),"Não","Sim") -> Não | L14: CNPJ, somente dígitos.
A15: cliente | B15: 3 | C15: razao_social | D15: VARCHAR(150) | H15: X | J15: =IF(OR(E15="X",H15="X"),"Não","Sim") -> Não | L15: Razão social.
A16: cliente | B16: 4 | C16: nome_fantasia | D16: VARCHAR(150) | J16: =IF(OR(E16="X",H16="X"),"Não","Sim") -> Sim | L16: Nome fantasia; opcional, usado na busca por CNPJ, razão social ou nome fantasia (UC14).
A17: cliente | B17: 5 | C17: nome_contato | D17: VARCHAR(100) | H17: X | J17: =IF(OR(E17="X",H17="X"),"Não","Sim") -> Não | L17: Nome do responsável/contato.
A18: cliente | B18: 6 | C18: telefone_contato | D18: VARCHAR(20) | J18: =IF(OR(E18="X",H18="X"),"Não","Sim") -> Sim | L18: Telefone de contato.
A19: cliente | B19: 7 | C19: email_contato | D19: VARCHAR(120) | J19: =IF(OR(E19="X",H19="X"),"Não","Sim") -> Sim | L19: E-mail de contato.
A20: cliente | B20: 8 | C20: tipo_unidade | D20: VARCHAR(6) | H20: X | I20: X | J20: =IF(OR(E20="X",H20="X"),"Não","Sim") -> Não | L20: MATRIZ ou FILIAL.
A21: cliente | B21: 9 | C21: status | D21: VARCHAR(9) | H21: X | I21: X | J21: =IF(OR(E21="X",H21="X"),"Não","Sim") -> Não | L21: ATIVO, INATIVO ou BLOQUEADO. Padrão: ATIVO.
A22: cliente | B22: 10 | C22: id_operador_vendedor | D22: INTEGER | F22: X | H22: X | J22: =IF(OR(E22="X",H22="X"),"Não","Sim") -> Não | K22: operador (id_operador) | L22: Vendedor responsável pela carteira do cliente.
A23: cliente | B23: 11 | C23: aceite_lgpd | D23: BOOLEAN | H23: X | I23: X | J23: =IF(OR(E23="X",H23="X"),"Não","Sim") -> Não | L23: Aceite da cláusula LGPD; só admite TRUE.
A24: cliente | B24: 12 | C24: data_aceite_lgpd | D24: TIMESTAMP | H24: X | J24: =IF(OR(E24="X",H24="X"),"Não","Sim") -> Não | L24: Data e hora do aceite da cláusula LGPD.
A25: cliente | B25: 13 | C25: data_cadastro | D25: TIMESTAMP | H25: X | J25: =IF(OR(E25="X",H25="X"),"Não","Sim") -> Não | L25: Data e hora do cadastro. Padrão: momento atual.
A26: endereco_cliente | B26: 1 | C26: id_endereco | D26: INTEGER | E26: X | J26: =IF(OR(E26="X",H26="X"),"Não","Sim") -> Não | L26: Identificador do endereço (auto-incremento).
A27: endereco_cliente | B27: 2 | C27: id_cliente | D27: INTEGER | F27: X | H27: X | J27: =IF(OR(E27="X",H27="X"),"Não","Sim") -> Não | K27: cliente (id_cliente) | L27: Cliente dono do endereço.
A28: endereco_cliente | B28: 3 | C28: tipo | D28: VARCHAR(10) | H28: X | I28: X | J28: =IF(OR(E28="X",H28="X"),"Não","Sim") -> Não | L28: CADASTRAL ou ENTREGA.
A29: endereco_cliente | B29: 4 | C29: logradouro | D29: VARCHAR(150) | H29: X | J29: =IF(OR(E29="X",H29="X"),"Não","Sim") -> Não | L29: Rua, avenida etc.
A30: endereco_cliente | B30: 5 | C30: numero | D30: VARCHAR(10) | H30: X | J30: =IF(OR(E30="X",H30="X"),"Não","Sim") -> Não | L30: Número (aceita 'S/N').
A31: endereco_cliente | B31: 6 | C31: complemento | D31: VARCHAR(60) | J31: =IF(OR(E31="X",H31="X"),"Não","Sim") -> Sim | L31: Complemento.
A32: endereco_cliente | B32: 7 | C32: bairro | D32: VARCHAR(80) | H32: X | J32: =IF(OR(E32="X",H32="X"),"Não","Sim") -> Não | L32: Bairro.
A33: endereco_cliente | B33: 8 | C33: cidade | D33: VARCHAR(80) | H33: X | J33: =IF(OR(E33="X",H33="X"),"Não","Sim") -> Não | L33: Cidade.
A34: endereco_cliente | B34: 9 | C34: uf | D34: CHAR(2) | H34: X | J34: =IF(OR(E34="X",H34="X"),"Não","Sim") -> Não | L34: Unidade da federação.
A35: endereco_cliente | B35: 10 | C35: cep | D35: CHAR(8) | H35: X | J35: =IF(OR(E35="X",H35="X"),"Não","Sim") -> Não | L35: CEP, somente dígitos.
A36: produto | B36: 1 | C36: id_produto | D36: INTEGER | E36: X | J36: =IF(OR(E36="X",H36="X"),"Não","Sim") -> Não | L36: Identificador do produto (auto-incremento).
A37: produto | B37: 2 | C37: codigo_interno | D37: VARCHAR(30) | G37: X | H37: X | J37: =IF(OR(E37="X",H37="X"),"Não","Sim") -> Não | L37: Código interno do produto.
A38: produto | B38: 3 | C38: descricao | D38: VARCHAR(200) | H38: X | J38: =IF(OR(E38="X",H38="X"),"Não","Sim") -> Não | L38: Descrição do produto.
A39: produto | B39: 4 | C39: ncm | D39: CHAR(8) | J39: =IF(OR(E39="X",H39="X"),"Não","Sim") -> Sim | L39: Classificação fiscal NCM; nulo quando não aplicável.
A40: produto | B40: 5 | C40: ean | D40: VARCHAR(14) | G40: X | J40: =IF(OR(E40="X",H40="X"),"Não","Sim") -> Sim | L40: Código de barras (EAN/GTIN); opcional.
...

Sheet Chaves Estrangeiras
A1: Chaves estrangeiras do modelo lógico
A2: Relações 1:N (lado N = tabela que contém a FK). Exceção: item_orcamento → reserva_estoque é 1:1 (id_item é FK e UK em reserva_estoque).
A4: Nº | B4: Tabela (lado N) | C4: Coluna (FK) | D4: Tabela referenciada (lado 1) | E4: Coluna referenciada | F4: Obrigatória
A5: 1 | B5: cliente | C5: id_operador_vendedor | D5: operador | E5: id_operador | F5: Sim
A6: 2 | B6: endereco_cliente | C6: id_cliente | D6: cliente | E6: id_cliente | F6: Sim
A7: 3 | B7: variacao_produto | C7: id_produto | D7: produto | E7: id_produto | F7: Sim
A8: 4 | B8: faixa_preco | C8: id_variacao | D8: variacao_produto | E8: id_variacao | F8: Sim
A9: 5 | B9: fardo | C9: id_variacao | D9: variacao_produto | E9: id_variacao | F9: Sim
A10: 6 | B10: orcamento | C10: id_cliente | D10: cliente | E10: id_cliente | F10: Sim
A11: 7 | B11: orcamento | C11: id_operador | D11: operador | E11: id_operador | F11: Sim
A12: 8 | B12: orcamento | C12: id_endereco_entrega | D12: endereco_cliente | E12: id_endereco | F12: Não
A13: 9 | B13: item_orcamento | C13: id_orcamento | D13: orcamento | E13: id_orcamento | F13: Sim
A14: 10 | B14: item_orcamento | C14: id_variacao | D14: variacao_produto | E14: id_variacao | F14: Sim
A15: 11 | B15: item_orcamento | C15: id_fardo | D15: fardo | E15: id_fardo | F15: Não
A16: 12 | B16: item_orcamento | C16: id_faixa_preco | D16: faixa_preco | E16: id_faixa_preco | F16: Não
... A49: 45 | B49: analise_credito | C49: id_operador_fiscal | D49: operador | E49: id_operador | F49: Não
